<?xml version="1.0"?>
<sdf version='1.4'>
  <world name='default'>
    <gui fullscreen='0'>
      <camera name='default-camera'>
        <pose>14.7795 -33.5495 17.2341 0 0.322119 1.72981</pose>
        <view_controller>orbit</view_controller>
      </camera>
    </gui>
    <scene>
      <sky>
        <clouds>
          <speed>1</speed>
        </clouds>
      </sky>
      <ambient>0.4 0.4 0.4 1</ambient>
      <background>0.7 0.7 0.7 1</background>
      <shadows>1</shadows>
    </scene>
    <light name='sun' type='directional'>
      <cast_shadows>1</cast_shadows>
      <pose>0 0 10 0 -0 0</pose>
      <diffuse>0.8 0.8 0.8 1</diffuse>
      <specular>0.2 0.2 0.2 1</specular>
      <attenuation>
        <range>1000</range>
        <constant>0.9</constant>
        <linear>0.01</linear>
        <quadratic>0.001</quadratic>
      </attenuation>
      <direction>-0.5 0.1 -0.9</direction>
    </light>
    <model name='land'>
      <pose>0 0 0 0 -0 0</pose>
      <static>1</static>
      <link name='body'>
        <visual name='visual'>
          <geometry>
            <mesh>
              <uri>file://meshes/land/landscape_with_background.dae</uri>
            </mesh>
          </geometry>
        </visual>
        <collision name='collision-land'>
          <geometry>
            <mesh>
              <uri>file://meshes/land/landscape_with_background.dae</uri>
            </mesh>
          </geometry>
          <max_contacts>10</max_contacts>
          <surface>
            <bounce/>
            <friction>
              <ode/>
            </friction>
            <contact>
              <ode/>
            </contact>
          </surface>
        </collision>
        <velocity_decay>
          <linear>0</linear>
          <angular>0</angular>
        </velocity_decay>
        <self_collide>0</self_collide>
        <kinematic>0</kinematic>
        <gravity>1</gravity>
      </link>
    </model>
    <physics type='ode'>
      <max_step_size>0.001</max_step_size>
      <real_time_factor>1</real_time_factor>
      <real_time_update_rate>1000</real_time_update_rate>
      <gravity>0 0 -9.8</gravity>
    </physics>
    <spherical_coordinates>
      <surface_model>EARTH_WGS84</surface_model>
      <latitude_deg>0</latitude_deg>
      <longitude_deg>0</longitude_deg>
      <elevation>0</elevation>
      <heading_deg>0</heading_deg>
    </spherical_coordinates>
    <model name='husky'>
      <pose>8.15817 -3.31395 5.248 0.01146 -0.051114 3.03412</pose>


<link name='base_link'>
  <collision name='collision'>
    <pose>0 0 0.1 0 -0 0</pose>
    <geometry>
      <box>
        <size>1.0074 0.5709 0.2675</size>
      </box>
    </geometry>
    <max_contacts>10</max_contacts>
    <surface>
      <bounce/>
      <friction>
        <ode/>
      </friction>
      <contact>
        <ode/>
      </contact>
    </surface>
  </collision>
  <inertial>
    <mass>33.855</mass>
    <pose>-0.0856132 -0.000839955 0.238145 0 -0 0</pose>
    <inertia>
      <ixx>2.2343</ixx>
      <ixy>-0.023642</ixy>
      <ixz>0.275174</ixz>
      <iyy>3.42518</iyy>
      <iyz>0.00239624</iyz>
      <izz>2.1241</izz>
    </inertia>
  </inertial>
  <visual name='base'>
    <pose>0 0 0 0 -0 0</pose>
    <geometry>
      <mesh>
        <uri>file://meshes/husky/base_link.stl</uri>
      </mesh>
    </geometry>
    <material>
      <script>
        <name>Gazebo/FlatBlack</name>
        <uri>__default__</uri>
      </script>
    </material>
  </visual>
  <visual name='top_plate'>
    <pose>0 0 0 0 -0 0</pose>
    <geometry>
      <mesh>
        <uri>file://meshes/husky/top_plate.stl</uri>
      </mesh>
    </geometry>
    <material>
      <script>
        <name>Gazebo/Yellow</name>
        <uri>__default__</uri>
      </script>
    </material>
  </visual>
  <visual name='front_bumper'>
    <pose>0.47 0 0.091 0 -0 0</pose>
    <geometry>
      <mesh>
        <uri>file://meshes/husky/bumper.stl</uri>
      </mesh>
    </geometry>
    <material>
      <script>
        <name>Gazebo/FlatBlack</name>
        <uri>__default__</uri>
      </script>
    </material>
  </visual>
  <visual name='rear_bumper'>
    <pose>-0.47 0 0.091 0 -0 3.141</pose>
    <geometry>
      <mesh>
        <uri>file://meshes/husky/bumper.stl</uri>
      </mesh>
    </geometry>
    <material>
      <script>
        <name>Gazebo/FlatBlack</name>
        <uri>__default__</uri>
      </script>
    </material>
  </visual>
  <visual name='user_rail'>
    <pose>0.272 0 0.245 0 -0 0</pose>
    <geometry>
      <mesh>
        <uri>file://meshes/husky/user_rail.stl</uri>
      </mesh>
    </geometry>
    <material>
      <script>
        <name>Gazebo/Grey</name>
        <uri>__default__</uri>
      </script>
    </material>
  </visual>
  <velocity_decay>
    <linear>0</linear>
    <angular>0</angular>
  </velocity_decay>
  <self_collide>0</self_collide>
  <kinematic>0</kinematic>
  <gravity>1</gravity>
</link>
<link name='back_left_wheel'>
  <pose>-0.256 0.285475 0.035 0 -0 0</pose>
  <inertial>
    <mass>2.6357</mass>
    <pose>0 0 0 0 -0 0</pose>
    <inertia>
      <ixx>0.0246688</ixx>
      <ixy>0</ixy>
      <ixz>0</ixz>
      <iyy>0.0246688</iyy>
      <iyz>0</iyz>
      <izz>0.0441058</izz>
    </inertia>
  </inertial>
  <collision name='back_left_wheel_collision'>
    <pose>0 0 0 -1.5707 0 0</pose>
    <geometry>
      <cylinder>
        <radius>0.17775</radius>
        <length>0.1143</length>
      </cylinder>
    </geometry>
    <surface>
      <friction>
        <ode>
          <mu>100000</mu>
          <mu2>100000</mu2>
          <slip1>0</slip1>
          <slip2>0</slip2>
        </ode>
      </friction>
      <bounce/>
      <contact>
        <ode/>
      </contact>
    </surface>
    <max_contacts>10</max_contacts>
  </collision>
  <visual name='back_left_wheel'>
    <pose>0 0 0 -3.14159 0 0</pose>
    <geometry>
      <mesh>
        <uri>file://meshes/husky/wheel.stl</uri>
      </mesh>
    </geometry>
    <material>
      <script>
        <name>Gazebo/Grey</name>
        <uri>__default__</uri>
      </script>
    </material>
  </visual>
  <velocity_decay>
    <linear>0</linear>
    <angular>0</angular>
  </velocity_decay>
  <self_collide>0</self_collide>
  <kinematic>0</kinematic>
  <gravity>1</gravity>
</link>
<joint name='back_left_joint' type='revolute'>
  <parent>base_link</parent>
  <child>back_left_wheel</child>
  <axis>
    <xyz>0 1 0</xyz>
    <limit>
      <lower>-1e+16</lower>
      <upper>1e+16</upper>
    </limit>
  </axis>
  <physics>
    <ode>
      <limit>
        <cfm>0</cfm>
        <erp>0.9</erp>
      </limit>
    </ode>
  </physics>
</joint>
<link name='back_right_wheel'>
  <pose>-0.256 -0.285475 0.035 0 -0 0</pose>
  <inertial>
    <mass>2.6357</mass>
    <pose>0 0 0 0 -0 0</pose>
    <inertia>
      <ixx>0.0246688</ixx>
      <ixy>0</ixy>
      <ixz>0</ixz>
      <iyy>0.0246688</iyy>
      <iyz>0</iyz>
      <izz>0.0441058</izz>
    </inertia>
  </inertial>
  <collision name='back_right_wheel_collision'>
    <pose>0 0 0 -1.5707 0 0</pose>
    <geometry>
      <cylinder>
        <radius>0.17775</radius>
        <length>0.1143</length>
      </cylinder>
    </geometry>
    <surface>
      <friction>
        <ode>
          <mu>100000</mu>
          <mu2>100000</mu2>
          <slip1>0</slip1>
          <slip2>0</slip2>
        </ode>
      </friction>
      <bounce/>
      <contact>
        <ode/>
      </contact>
    </surface>
    <max_contacts>10</max_contacts>
  </collision>
  <visual name='back_right_wheel'>
    <pose>0 0 0 -3.14159 0 0</pose>
    <geometry>
      <mesh>
        <uri>file://meshes/husky/wheel.stl</uri>
      </mesh>
    </geometry>
    <material>
      <script>
        <name>Gazebo/Grey</name>
        <uri>__default__</uri>
      </script>
    </material>
  </visual>
  <velocity_decay>
    <linear>0</linear>
    <angular>0</angular>
  </velocity_decay>
  <self_collide>0</self_collide>
  <kinematic>0</kinematic>
  <gravity>1</gravity>
</link>
<joint name='back_right_joint' type='revolute'>
  <parent>base_link</parent>
  <child>back_right_wheel</child>
  <axis>
    <xyz>0 1 0</xyz>
    <limit>
      <lower>-1e+16</lower>
      <upper>1e+16</upper>
    </limit>
  </axis>
  <physics>
    <ode>
      <limit>
        <cfm>0</cfm>
        <erp>0.9</erp>
      </limit>
    </ode>
  </physics>
</joint>
<link name='front_left_wheel'>
  <pose>0.256 0.285475 0.035 0 -0 0</pose>
  <inertial>
    <mass>2.6357</mass>
    <pose>0 0 0 0 -0 0</pose>
    <inertia>
      <ixx>0.0246688</ixx>
      <ixy>0</ixy>
      <ixz>0</ixz>
      <iyy>0.0246688</iyy>
      <iyz>0</iyz>
      <izz>0.0441058</izz>
    </inertia>
  </inertial>
  <collision name='front_left_wheel_collision'>
    <pose>0 0 0 -1.5707 0 0</pose>
    <geometry>
      <cylinder>
        <radius>0.17775</radius>
        <length>0.1143</length>
      </cylinder>
    </geometry>
    <surface>
      <friction>
        <ode>
          <mu>100000</mu>
          <mu2>100000</mu2>
          <slip1>0</slip1>
          <slip2>0</slip2>
        </ode>
      </friction>
      <bounce/>
      <contact>
        <ode/>
      </contact>
    </surface>
    <max_contacts>10</max_contacts>
  </collision>
  <visual name='front_left_wheel'>
    <pose>0 0 0 -3.14159 0 0</pose>
    <geometry>
      <mesh>
        <uri>file://meshes/husky/wheel.stl</uri>
      </mesh>
    </geometry>
    <material>
      <script>
        <name>Gazebo/Grey</name>
        <uri>__default__</uri>
      </script>
    </material>
  </visual>
  <velocity_decay>
    <linear>0</linear>
    <angular>0</angular>
  </velocity_decay>
  <self_collide>0</self_collide>
  <kinematic>0</kinematic>
  <gravity>1</gravity>
</link>
<joint name='front_left_joint' type='revolute'>
  <parent>base_link</parent>
  <child>front_left_wheel</child>
  <axis>
    <xyz>0 1 0</xyz>
    <limit>
      <lower>-1e+16</lower>
      <upper>1e+16</upper>
    </limit>
  </axis>
  <physics>
    <ode>
      <limit>
        <cfm>0</cfm>
        <erp>0.9</erp>
      </limit>
    </ode>
  </physics>
</joint>
<link name='front_right_wheel'>
  <pose>0.256 -0.285475 0.035 0 -0 0</pose>
  <inertial>
    <mass>2.6357</mass>
    <pose>0 0 0 0 -0 0</pose>
    <inertia>
      <ixx>0.0246688</ixx>
      <ixy>0</ixy>
      <ixz>0</ixz>
      <iyy>0.0246688</iyy>
      <iyz>0</iyz>
      <izz>0.0441058</izz>
    </inertia>
  </inertial>
  <collision name='front_right_wheel_collision'>
    <pose>0 0 0 -1.5707 0 0</pose>
    <geometry>
      <cylinder>
        <radius>0.17775</radius>
        <length>0.1143</length>
      </cylinder>
    </geometry>
    <surface>
      <friction>
        <ode>
          <mu>100000</mu>
          <mu2>100000</mu2>
          <slip1>0</slip1>
          <slip2>0</slip2>
        </ode>
      </friction>
      <bounce/>
      <contact>
        <ode/>
      </contact>
    </surface>
    <max_contacts>10</max_contacts>
  </collision>
  <visual name='front_right_wheel'>
    <pose>0 0 0 -3.14159 0 0</pose>
    <geometry>
      <mesh>
        <uri>file://meshes/husky/wheel.stl</uri>
      </mesh>
    </geometry>
    <material>
      <script>
        <name>Gazebo/Grey</name>
        <uri>__default__</uri>
      </script>
    </material>
  </visual>
  <velocity_decay>
    <linear>0</linear>
    <angular>0</angular>
  </velocity_decay>
  <self_collide>0</self_collide>
  <kinematic>0</kinematic>
  <gravity>1</gravity>
</link>
<joint name='front_right_joint' type='revolute'>
  <parent>base_link</parent>
  <child>front_right_wheel</child>
  <axis>
    <xyz>0 1 0</xyz>
    <limit>
      <lower>-1e+16</lower>
      <upper>1e+16</upper>
    </limit>
  </axis>
  <physics>
    <ode>
      <limit>
        <cfm>0</cfm>
        <erp>0.9</erp>
      </limit>
    </ode>
  </physics>
</joint>
<plugin name='husky_diff_controller' filename='libhusky_gazebo_plugins.so'>
  <alwaysOn>true</alwaysOn>
  <updateRate>100.0</updateRate>
  <backLeftJoint>back_left_joint</backLeftJoint>
  <backRightJoint>back_right_joint</backRightJoint>
  <frontLeftJoint>front_left_joint</frontLeftJoint>
  <frontRightJoint>front_right_joint</frontRightJoint>
  <wheelSeparation>0.5709</wheelSeparation>
  <wheelDiameter>0.3555</wheelDiameter>
  <torque>35</torque>
</plugin>
<static>0</static>
      <!--include>
        <uri>
          model://stereo_camera
        </uri>
        <pose>0 0 .3 0 0 0</pose>
      </include-->

    <link name="stereocamera">
      <pose>0 0 .5 0 0 0</pose>
      <inertial>
        <mass>0.1</mass>
      </inertial>

      <collision name="collision">
        <geometry>
          <box>
            <size>0.1 0.1 0.1</size>
          </box>
        </geometry>
      </collision>

      <visual name="visual">
        <geometry>
          <box>
            <size>0.1 0.1 0.1</size>
          </box>
        </geometry>
      </visual>

      <sensor name="camera" type="multicamera">
        <always_on>1</always_on>
        <update_rate>3</update_rate>
        <visualize>false</visualize>

        <camera name="left">
          <pose>0 0.2 0 0 0 0</pose>
          <horizontal_fov>1.047</horizontal_fov>
          <image>
            <width>960</width>
            <height>720</height>
          </image>
          <clip>
            <near>0.1</near>
            <far>1000</far>
          </clip>
        </camera>

        <camera name="right">
          <pose>0 -0.2 0 0 0 0</pose>
          <horizontal_fov>1.047</horizontal_fov>
          <image>
            <width>960</width>
            <height>720</height>
          </image>
          <clip>
            <near>0.1</near>
            <far>1000</far>
          </clip>
        </camera>
      <plugin name="camera_controller" filename="libgazebo_ros_multicamera.so">
        <alwaysOn>true</alwaysOn>
        <updateRate>0.0</updateRate>
        <cameraName>rrbot/camera1</cameraName>
        <imageTopicName>image_raw</imageTopicName>
        <cameraInfoTopicName>camera_info</cameraInfoTopicName>
        <!--frameName>base_link</frameName-->
        <frameName>camera</frameName>
     
        <hackBaseline>0.07</hackBaseline>
        <distortionK1>0.0</distortionK1>
        <distortionK2>0.0</distortionK2>
        <distortionK3>0.0</distortionK3>
        <distortionT1>0.0</distortionT1>
        <distortionT2>0.0</distortionT2>
      </plugin>
      </sensor>
    </link>
      <joint name="stereo_camera_joint" type="revolute">
        <child>stereocamera</child>
        <parent>base_link</parent>
        <axis>
          <xyz>0 0 1</xyz>
          <limit>
            <upper>0</upper>
            <lower>0</lower>
          </limit>
  </axis></lower></upper></limit></xyz></axis>
</joint>

    </model>
  </world>
</sdf>
